Workbook

Sheet 1-Study Identification
A1: Study Identification
A2: Study ID | B2: Title | C2: DOI | D2: Year
A3: SCOPUS-000349 | B3: Drone-Aided Detection of Weeds: Transfer Learning for Embedded Image Processing | C3: 10.1109/JSTARS.2022.3224657 | D3: 2022
A4: SCOPUS-000473 | B4: ConvNeXt based semi-supervised approach with consistency regularization for weeds classification | C4: 10.1016/j.eswa.2023.122222 | D4: 2024
A5: SCOPUS-000722 | B5: DeepVeg- Deep Learning Model for Segmentation of Weed, Canola, and Canola Flea Beetle Damage | C5: 10.1109/ACCESS.2021.3108003 | D5: 2021
A6: SCOPUS-000153 | B6: UNET-SA: A Spatial Attention Enhanced UNET for Crop–Weed Segmentation in UAV-Based Pigeon Pea Fields | C6: 10.32985/ijeces.17.4.1 | D6: 2026
A7: SCOPUS-000522 | B7: Intelligent Weed Management Based on Object Detection Neural Networks in Tomato Crops | C7: 10.3390/agronomy12122953 | D7: 2022
A8: SCOPUS-000487 | B8: Multi-Spectral Image Synthesis for Crop/Weed Segmentation in Precision Farming | C8: 10.1016/j.robot.2021.103861 | D8: 2021
A9: SCOPUS-000328 | B9: Multi-level feature re-weighted fusion for the semantic segmentation of crops and weeds | C9: 10.1016/j.jksuci.2023.03.023 | D9: 2023
A10: SCOPUS-000234 | B10: YOLOv8 Model for Weed Detection in Wheat Fields Based on a Visual Converter and Multi-Scale Feature Fusion | C10: 10.3390/s24134379 | D10: 2024
A11: SCOPUS-000220 | B11: YOLO-SW: A Real-Time Weed Detection Model for Soybean Fields Using Swin Transformer and RT-DETR | C11: 10.3390/agronomy15071712 | D11: 2025
A12: SCOPUS-000195 | B12: Smart weed recognition in saffron fields based on an improved EfficientNetB0 model and RGB images | C12: 10.1038/s41598-025-00331-9 | D12: 2025
A13: SCOPUS-000139 | B13: Generative AI-based pipeline architecture for increasing training efficiency in intelligent weed control systems | C13: 10.1016/j.sysarc.2025.103464 | D13: 2025
... A24: SCOPUS-000611 | B24: A Lightweight Deep Learning Model for Identifying Weeds in Corn and Soybean Using Quantization | C24: 10.3390/ASEC2023-15811 | D24: 2023
A25: SCOPUS-000738 | B25: A Patch-Image Based Classification Approach for Detection of Weeds in Sugar Beet Crop | C25: 10.1109/ACCESS.2021.3109015 | D25: 2021
A26: SCOPUS-000114 | B26: Advanced classification techniques for weed and crop species recognition using machine learning algorithms | C26: 10.11591/ijaas.v14.i2.pp300-309 | D26: 2025
A27: SCOPUS-000366 | B27: A Combination of Transfer Learning and Support Vector Machine for Robust Classification on Small Weed and Potato Datasets | C27: 10.30630/joiv.7.2.1164 | D27: 2023
A28: SCOPUS-000283 | B28: TARGET DETECTION FOR WEEDING ROBOTS BASED ON IMPROVED YOLOv11 MODELS | C28: 10.1590/1809-4430-Eng.Agric.v45e20250032/2025 | D28: 2025
A29: SCOPUS-000276 | B29: Hybrid Attention-Based Prototypical Network for Weed Identification in Precision Agriculture | C29: 10.1007/s41314-025-00070-9 | D29: 2025
A30: SCOPUS-000246 | B30: Exploiting adversarial style for generalized and robust weed segmentation in rice paddy field | C30: 10.3389/fpls.2025.1703811 | D30: 2025
A31: SCOPUS-000599 | B31: Transfer Learning-based Weed Classification and Detection for Precision Agriculture | C31: 10.14569/IJACSA.2024.0150646 | D31: 2024
A32: SCOPUS-000280 | B32: YOLOv12-BDA: A Dynamic Multi-Scale Architecture for Small Weed Detection in Sesame Fields | C32: 10.3390/s25226927 | D32: 2025
A33: SCOPUS-000063 | B33: A Semi-Supervised Diffusion-Based Framework for Weed Detection in Precision Agricultural Scenarios Using a Generative Attention Mechanism | C33: 10.3390/agriculture15040434 | D33: 2025
A34: SCOPUS-000017 | B34: MSEA-Net: Multi-Scale and Edge-Aware Network for Weed Segmentation | C34: 10.3390/agriengineering7040103 | D34: 2025
A35: SCOPUS-000244 | B35: WeedCLR: Weed contrastive learning through visual representations with class-optimized loss in long-tailed datasets | C35: 10.1016/j.compag.2024.109526 | D35: 2024
A36: SCOPUS-000320 | B36: YOLOv7 for Weed Detection in Cotton Fields Using UAV Imagery | C36: 10.3390/agriengineering7100313 | D36: 2025
A37: SCOPUS-000086 | B37: Semi-supervised weed detection for rapid deployment and enhanced efficiency | C37: 10.1016/j.compag.2025.110410 | D37: 2025
A38: SCOPUS-000652 | B38: Developing an extreme learning machine based approach to weed segmentation in pastures | C38: 10.1016/j.atech.2023.100288 | D38: 2023
A39: SCOPUS-000146 | B39: Addressing computation resource exhaustion associated with deep learning training of three-dimensional hyperspectral images using multiclass weed classification | C39: 10.1016/j.aiia.2025.02.005 | D39: 2025
A40: SCOPUS-000352 | B40: An Improved UNet Lightweight Network for Semantic Segmentation of Weed Images in Corn Fields | C40: 10.32604/cmc.2024.049805 | D40: 2024
A41: SCOPUS-000175 | B41: PD-YOLO: a novel weed detection method based on multi-scale feature fusion | C41: 10.3389/fpls.2025.1506524 | D41: 2025
A42: SCOPUS-000574 | B42: Overcoming field variability: unsupervised domain adaptation for enhanced crop-weed recognition in diverse farmlands | C42: 10.3389/fpls.2023.1234616 | D42: 2023
A43: SCOPUS-000358 | B43: SC-Net: A new strip convolutional network model for rice seedling and weed segmentation in paddy field | C43: 10.1016/j.compag.2024.108862 | D43: 2024
... A74: SCOPUS-000065 | B74: Class imbalance aware deep semantic segmentation framework for weed and tobacco crops in UAV imagery | C74: 10.3389/frai.2026.1792086 | D74: 2026
A75: SCOPUS-000030 | B75: Balancing accuracy and cost in precision agriculture: a few-shot learning approach for efficient weed − crop segmentation | C75: 10.1016/j.compag.2026.111524 | D75: 2026
A76: WEBSCI-000402 | B76: Enhancing weed detection in wheat with hybrid attention mechanism CBAM: a comparative study with deep learning approaches | C76: 10.3389/fagro.2026.1706873 | D76: 2026
A77: SCOPUS-000300 | B77: WeedCAM: An edge-computing camera system for multi-species weed detection in sugar beet production fields | C77: 10.1016/j.compag.2026.111498 | D77: 2026
A78: SCOPUS-000099 | B78: Detection and variable spraying of maize and weeds in residue covered fields via occlusion-aware modeling | C78: 10.1016/j.aiia.2026.04.004 | D78: 2026
A79: SCOPUS-000287 | B79: Multispecies weed mapping using deep learning on UAV imagery for SSWM in maize and tomato | C79: 10.1007/s11119-025-10309-2 | D79: 2026
A80: SCOPUS-000290 | B80: Optimization and Experimental Evaluation of a Deep Learning-Based Target Spraying Device for Weed Control in Soybean Fields | C80: 10.3390/agriculture16040395 | D80: 2026
...

Sheet 2-Application Context
A1: Application Context
A2: Study ID | B2: Task | C2: Crop | D2: Environment
A3: SCOPUS-000349 | B3: Segmentation | C3: None | D3: UAV aerial
A4: SCOPUS-000473 | B4: Classification | C4: Mixed | D4: Field
A5: SCOPUS-000722 | B5: Segmentation | C5: Canola | D5: Field
A6: SCOPUS-000153 | B6: Segmentation | C6: Pigeon pea | D6: Field: mobile camera (1,634 images) and UAV drone (93 images)
A7: SCOPUS-000522 | B7: Detection | C7: Tomato | D7: Field
A8: SCOPUS-000487 | B8: Segmentation | C8: Mixed | D8: Field
A9: SCOPUS-000328 | B9: Segmentation | C9: Mixed | D9: Field
A10: SCOPUS-000234 | B10: Detection | C10: Wheat | D10: Field
A11: SCOPUS-000220 | B11: Detection | C11: Soybean | D11: Field
A12: SCOPUS-000195 | B12: Classification | C12: Saffron | D12: Field
A13: SCOPUS-000139 | B13: Detection | C13: Sugar beet | D13: Field
... A141: WEBSCI-000559 | B141: Classification | C141: Maize | D141: Field

Sheet 4-Dataset Characteristics
A1: Dataset Characteristics
A2: Study ID | B2: Dataset | C2: Dataset Availability | D2: Dataset Size | E2: Country
A3: SCOPUS-000349 | C3: Public | D3: >20,000 training crops; 83 evaluation crops
A4: SCOPUS-000473 | B4: DeepWeeds, 4-Weeds dataset, and CIFAR-10 | C4: Public | D4: 17509 | E4: Australia
A5: SCOPUS-000722 | B5: Canola field image dataset | C5: Private | D5: 384 | E5: Canada
A6: SCOPUS-000153 | B6: Pigeon Pea dataset | D6: 1727 | E6: India
A7: SCOPUS-000522 | C7: Private | D7: 1713 | E7: Spain
A8: SCOPUS-000487 | B8: Bonn dataset | C8: Public | D8: 2100 | E8: Germany
A9: SCOPUS-000328 | B9: BoniRob, CWFID, and Rice seedling datasets | D9: 776
A10: SCOPUS-000234 | B10: Wheat Weed Dataset | C10: Private | D10: 4536 | E10: China
A11: SCOPUS-000220 | B11: Soybean weed dataset | C11: Public | D11: 1095 | E11: China
A12: SCOPUS-000195 | B12: Saffron weed dataset | C12: On Request | D12: 504 | E12: Iran
A13: SCOPUS-000139 | B13: Sugar beet dataset | C13: Public | D13: 2074 | E13: Germany
A14: SCOPUS-000045 | B14: Bonn sugar beet dataset | C14: Public | D14: 1600 | E14: Germany
A15: SCOPUS-000031 | B15: CropAndWeed Dataset and SB20 Dataset | C15: Public | D15: 7795 | E15: Germany
A16: SCOPUS-000014 | B16: CropAndWeed Dataset | C16: Public | D16: 7705 | E16: Austria
A17: SCOPUS-000544 | B17: Maize weed dataset | C17: Private | D17: 5856 | E17: China
A18: SCOPUS-000592 | C18: On Request | D18: 300 | E18: China
A19: SCOPUS-000629 | C19: On Request | D19: 884 | E19: Spain
A20: SCOPUS-000475 | B20: Sugarbeets2016 and Flourish Sapienza Datasets | C20: Public | D20: 465 | E20: Germany, Italy
A21: SCOPUS-000399 | B21: sPSD and ISAS (Institute for Sustainable Agro-ecosystem Services) dataset | C21: Public | D21: 6094 | E21: Denmark, Japan
A22: SCOPUS-000323 | B22: SorghumWeedDataset_Classification | C22: Public | D22: 4312
A23: SCOPUS-000295 | C23: Private | D23: 1500 | E23: China
A24: SCOPUS-000611 | B24: Combined dataset | C24: Public | D24: 13177 | E24: China
A25: SCOPUS-000738 | B25: Agrocam, Red Edge, and Parrot Sequoia datasets | C25: Public | D25: 679 | E25: Pakistan, Switzerland, Germany
A26: SCOPUS-000114 | B26: Custom image dataset | C26: Public | D26: 11500
A27: SCOPUS-000366 | B27: Kaggle Potato Weed Plants Classification | C27: Public | D27: 411
A28: SCOPUS-000283 | B28: Maize and weed dataset | C28: On Request | D28: 4465 | E28: China
A29: SCOPUS-000276 | B29: DeepWeeds | C29: Public | D29: 17509
A30: SCOPUS-000246 | B30: Custom paddy weed dataset (laboratory and field subsets) | D30: 3800 | E30: China
A31: SCOPUS-000599 | B31: Oil palm plantation weed dataset | D31: 2377 | E31: Malaysia
A32: SCOPUS-000280 | B32: Sesame dataset and Crop and Weed Detection Data with Bounding Boxes | C32: Public | D32: 4122
A33: SCOPUS-000063 | C33: On Request | D33: 7662 | E33: China
A34: SCOPUS-000017 | B34: CoFly-WeedDB and Sorghum Fields | C34: Public | D34: 7086 | E34: Greece, Germany
A35: SCOPUS-000244 | B35: DeepWeeds and CottonWeedID15 | C35: Public | D35: 22696 | E35: USA, Australia
A36: SCOPUS-000320 | B36: Cotton weed dataset | C36: Public | D36: 9249 | E36: USA
A37: SCOPUS-000086 | B37: MS-COCO, CottonWeedDet12, CropAndWeed, Palmer Amaranth, RadishWheat, and RoboWeedMap | C37: Public
A38: SCOPUS-000652 | B38: Bathurst burr, horehound, thistle, and tussock datasets | C38: Private | E38: Australia
A39: SCOPUS-000146 | B39: Weedcube | C39: Public | D39: 1072 | E39: USA
A40: SCOPUS-000352 | B40: Corn weed datasets | C40: Public | D40: 1024 | E40: China
...

Sheet 5-Barrier Coding
A1: Training Data Barriers
A2: Study ID | B2: Study Instance ID | C2: Barrier Category | D2: Modules | E2: Barriers
A3: SCOPUS-000349 | B3: SCOPUS-000349-1 | C3: TECHNICAL | D3: Dual-camera setup | E3: Computational Resource
A4: SCOPUS-000349 | B4: SCOPUS-000349-2 | C4: IMAGING | D4: Multispectral cameras | E4: Image Alignment
A5: SCOPUS-000473 | B5: SCOPUS-000473-1 | C5: DATA | D5: Efficientnet-V2-L | E5: Data Scarcity
A6: SCOPUS-000473 | B6: SCOPUS-000473-2 | C6: ENVIRONMENTAL | D6: Efficientnet-V2-L | E6: Environmental Variation
A7: SCOPUS-000722 | B7: SCOPUS-000722-1 | C7: DATA | D7: DeepLabV3+ | E7: Class Imbalance
A8: SCOPUS-000153 | B8: SCOPUS-000153-1 | C8: DATA | D8: UNet | E8: Annotation
A9: SCOPUS-000153 | B9: SCOPUS-000153-2 | C9: IMAGING | D9: UNet | E9: Small Object Detection
A10: SCOPUS-000522 | B10: SCOPUS-000522-1 | C10: ENVIRONMENTAL | D10: YOLOv7 | E10: Background Complexity
A11: SCOPUS-000522 | B11: SCOPUS-000522-2 | C11: DATA | D11: YOLOv7 | E11: Data Scarcity
A12: SCOPUS-000487 | B12: SCOPUS-000487-1 | C12: DATA | D12: SegNet Original | E12: Data Scarcity
A13: SCOPUS-000328 | B13: SCOPUS-000328-1 | C13: ENVIRONMENTAL | E13: Background Complexity
A14: SCOPUS-000234 | B14: SCOPUS-000234-1 | C14: IMAGING | D14: YOLOv3 | E14: Scale Variation
A15: SCOPUS-000220 | B15: SCOPUS-000220-1 | C15: ENVIRONMENTAL | D15: YOLOv8 | E15: Background Complexity
A16: SCOPUS-000220 | B16: SCOPUS-000220-2 | C16: IMAGING | D16: Bilinear interpolation | E16: Small Object Detection
A17: SCOPUS-000195 | B17: SCOPUS-000195-1 | C17: IMAGING | D17: Base EfficientNetB0 | E17: Visual Similarity
A18: SCOPUS-000139 | B18: SCOPUS-000139-1 | C18: DATA | D18: YOLOv10n | E18: Data Scarcity
A19: SCOPUS-000139 | B19: SCOPUS-000139-2 | C19: ENVIRONMENTAL | D19: YOLOv10n | E19: Background Complexity
A20: SCOPUS-000045 | B20: SCOPUS-000045-1 | C20: DATA | D20: Bonnet | E20: Class Imbalance
A21: SCOPUS-000031 | B21: SCOPUS-000031-1 | C21: TECHNICAL | D21: FCN | E21: Feature Representation
A22: SCOPUS-000014 | B22: SCOPUS-000014-1 | C22: IMAGING | D22: RetinaNet | E22: Visual Similarity
A23: SCOPUS-000544 | B23: SCOPUS-000544-1 | C23: ENVIRONMENTAL | D23: PolarMask | E23: Background Complexity
A24: SCOPUS-000592 | B24: SCOPUS-000592-1 | C24: DATA | D24: DeepLab-V3+ | E24: Annotation
A25: SCOPUS-000592 | B25: SCOPUS-000592-2 | C25: TECHNICAL | D25: Xception | E25: Computational Resource
... A50: SCOPUS-000244 | B50: SCOPUS-000244-2 | C50: DATA | D50: BYOL | E50: Annotation
A51: SCOPUS-000320 | B51: SCOPUS-000320-1 | C51: DATA | E51: Class Imbalance
A52: SCOPUS-000086 | B52: SCOPUS-000086-1 | C52: DATA | D52: Supervised | E52: Data Scarcity
A53: SCOPUS-000652 | B53: SCOPUS-000652-1 | C53: IMAGING | D53: Vegetation Index | E53: Visual Similarity
A54: SCOPUS-000652 | B54: SCOPUS-000652-2 | C54: ENVIRONMENTAL | E54: Occlusion
A55: SCOPUS-000146 | B55: SCOPUS-000146-1 | C55: TECHNICAL | D55: VGG-16 | E55: Computational Resource
A56: SCOPUS-000146 | B56: SCOPUS-000146-2 | C56: TECHNICAL | D56: Unfolded/tabular HSI approaches | E56: Feature Representation
A57: SCOPUS-000352 | B57: SCOPUS-000352-1 | C57: TECHNICAL | D57: UNet | E57: Computational Resource
A58: SCOPUS-000352 | B58: SCOPUS-000352-2 | C58: DATA | E58: Data Scarcity
A59: SCOPUS-000175 | B59: SCOPUS-000175-1 | C59: IMAGING | D59: YOLOv8n | E59: Visual Similarity
A60: SCOPUS-000175 | B60: SCOPUS-000175-2 | C60: ENVIRONMENTAL | E60: Occlusion
A61: SCOPUS-000574 | B61: SCOPUS-000574-1 | C61: ENVIRONMENTAL | D61: DeepLab V3+ | E61: Domain Shift
A62: SCOPUS-000358 | B62: SCOPUS-000358-1 | C62: IMAGING | D62: SegNet | E62: Visual Similarity
A63: SCOPUS-000265 | B63: SCOPUS-000265-1 | C63: ENVIRONMENTAL | D63: Faster RCNN | E63: Occlusion
A64: SCOPUS-000265 | B64: SCOPUS-000265-2 | C64: IMAGING | D64: Faster RCNN | E64: Scale Variation
...

Sheet 6-Mitigation Strategy Coding
A1: Mitigation Strategies
A2: Study ID | B2: Study Instance ID | C2: Mitigation Category | D2: Mitigations
A3: SCOPUS-000349 | B3: SCOPUS-000349-1 | C3: Data-Centric | D3: Transfer Learning
A4: SCOPUS-000349 | B4: SCOPUS-000349-2 | C4: Architectural | D4: Architecture Modification
A5: SCOPUS-000473 | B5: SCOPUS-000473-1 | C5: Architectural | D5: Architecture Modification
A6: SCOPUS-000473 | B6: SCOPUS-000473-2 | C6: Architectural | D6: Loss Function Modification
A7: SCOPUS-000722 | B7: SCOPUS-000722-1 | C7: Architectural | D7: Loss Function Modification
A8: SCOPUS-000153 | B8: SCOPUS-000153-1 | C8: Data-Centric | D8: Data Processing
A9: SCOPUS-000153 | B9: SCOPUS-000153-2 | C9: Architectural | D9: Attention Mechanism
A10: SCOPUS-000522 | B10: SCOPUS-000522-1 | C10: Architectural | D10: Architecture Modification
A11: SCOPUS-000522 | B11: SCOPUS-000522-2 | C11: Data-Centric | D11: Data Augmentation
A12: SCOPUS-000487 | B12: SCOPUS-000487-1 | C12: Data-Centric | D12: Synthetic Data Generation
A13: SCOPUS-000328 | B13: SCOPUS-000328-1 | C13: Architectural | D13: Attention Mechanism
... A416: WEBSCI-000559 | B416: WEBSCI-000559-4 | C416: Data-Centric | D416: Data Augmentation

Sheet 7-Baseline Performance Results
A1: Barriers-Results
A2: Study ID | B2: Study Instance ID | C2: Baseline Modules | D2: Metric Family | E2: Baseline (%)
A3: SCOPUS-000349 | B3: SCOPUS-000349-1 | C3: SynthNoRGN (frame-trained, test-field orthophoto) | D3: mIoU | E3: 54.5
A4: SCOPUS-000473 | B4: SCOPUS-000473-2 | C4: ConvNeXt-Base-SSL without skip connections | D4: Accuracy | E4: 91.09
A5: SCOPUS-000722 | B5: SCOPUS-000722-1 | C5: DeepLabV3+ VGG19 | D5: mIoU | E5: 56.4739
A6: SCOPUS-000153 | B6: SCOPUS-000153-1 | C6: PAN | D6: mIoU | E6: 77.93
A7: SCOPUS-000522 | B7: SCOPUS-000522-3 | C7: RetinaNet | D7: mAP@0.5 | E7: 90.354
A8: SCOPUS-000487 | B8: SCOPUS-000487-4 | C8: Bonnet Original | D8: mIoU | E8: 70
A9: SCOPUS-000328 | B9: SCOPUS-000328-2 | C9: Baseline (paper's own base architecture, Table 4) | D9: mIoU | E9: 88.53
A10: SCOPUS-000234 | B10: SCOPUS-000234-1 | C10: YOLOv3 | D10: mAP@0.5 | E10: 73.1
A11: SCOPUS-000220 | B11: SCOPUS-000220-2 | C11: YOLOv8n | D11: mAP@0.5 | E11: 88.3
A12: SCOPUS-000195 | B12: SCOPUS-000195-1 | C12: ResNet152 (Model 2) | D12: Accuracy | E12: 40
A13: SCOPUS-000139 | B13: SCOPUS-000139-3 | C13: YOLOv9s (Real data only) | D13: mAP@0.5 | E13: 88.7
A14: SCOPUS-000045 | B14: SCOPUS-000045-2 | C14: Original (RGB + NIR) | D14: mIoU | E14: 77
... A141: SCOPUS-000030 | B141: SCOPUS-000030-T1 | C141: HDMNet COCO-pretrained, 1-shot support, Early 2023 | D141: mIoU | E141: 26.35

Sheet 8-Mitigation Performance Result
A1: Mitigation-Results
A2: Study ID | B2: Study Instance ID | C2: Mitigation Modules | D2: Metric Family | E2: Mitigation (%) | F2: Gain (pp)
A3: SCOPUS-000349 | B3: SCOPUS-000349-3 | C3: SynthFakeRGN+TL (frame-trained, test-field orthophoto) | D3: mIoU | E3: 60.4 | F3: =ROUND(VALUE(E3)-'7-Baseline Performance Results'!E3,4) -> 5.9
A4: SCOPUS-000473 | B4: SCOPUS-000473-2 | C4: ConvNeXt-Base-SSL with skip connections | D4: Accuracy | E4: 92.33 | F4: =ROUND(VALUE(E4)-'7-Baseline Performance Results'!E4,4) -> 1.24
A5: SCOPUS-000722 | B5: SCOPUS-000722-1 | C5: Proposed | D5: mIoU | E5: 76.79226 | F5: =ROUND(VALUE(E5)-'7-Baseline Performance Results'!E5,4) -> 20.3184
A6: SCOPUS-000153 | B6: SCOPUS-000153-10 | C6: UNET-SA | D6: mIoU | E6: 94.49 | F6: =ROUND(VALUE(E6)-'7-Baseline Performance Results'!E6,4) -> 16.56
A7: SCOPUS-000522 | B7: SCOPUS-000522-3 | C7: RetinaNet and Augmentation | D7: mAP@0.5 | E7: 92.755 | F7: =ROUND(VALUE(E7)-'7-Baseline Performance Results'!E7,4) -> 2.401
A8: SCOPUS-000487 | B8: SCOPUS-000487-4 | C8: Bonnet Mixed | D8: mIoU | E8: 76 | F8: =ROUND(VALUE(E8)-'7-Baseline Performance Results'!E8,4) -> 6
A9: SCOPUS-000328 | B9: SCOPUS-000328-5 | C9: MTS-CNN | D9: mIoU | E9: 91.64 | F9: =ROUND(VALUE(E9)-'7-Baseline Performance Results'!E9,4) -> 3.11
A10: SCOPUS-000234 | B10: SCOPUS-000234-5 | C10: YOLOv8-C2f_M3-BiFPN-MPDIoU | D10: mAP@0.5 | E10: 89.7 | F10: =ROUND(VALUE(E10)-'7-Baseline Performance Results'!E10,4) -> 16.6
A11: SCOPUS-000220 | B11: SCOPUS-000220-2 | C11: YOLO-SW | D11: mAP@0.5 | E11: 92.3 | F11: =ROUND(VALUE(E11)-'7-Baseline Performance Results'!E11,4) -> 4
A12: SCOPUS-000195 | B12: SCOPUS-000195-1 | C12: Improved EfficientNetB0 (Model 5) | D12: Accuracy | E12: 94.06 | F12: =ROUND(VALUE(E12)-'7-Baseline Performance Results'!E12,4) -> 54.06
A13: SCOPUS-000045 | B13: SCOPUS-000045-2 | C13: Mixed (RGB + NIR) | D13: mIoU | E13: 82 | F13: =ROUND(VALUE(E13)-'7-Baseline Performance Results'!E14,4) -> 5
A14: SCOPUS-000031 | B14: SCOPUS-000031-6 | C14: SWFormer | D14: mIoU | E14: 61.24 | F14: =ROUND(VALUE(E14)-'7-Baseline Performance Results'!E15,4) -> 9.24
A15: SCOPUS-000014 | B15: SCOPUS-000014-3 | C15: HDMS-YOLO | D15: mAP@0.5 | E15: 71.2 | F15: =ROUND(VALUE(E15)-'7-Baseline Performance Results'!E16,4) -> 2.6
A16: SCOPUS-000544 | B16: SCOPUS-000544-1 | C16: ResNet101 backbone (with data enhancement) | D16: mIoU | E16: 60.7 | F16: =ROUND(VALUE(E16)-'7-Baseline Performance Results'!E17,4) -> 10.5
A17: SCOPUS-000592 | B17: SCOPUS-000592-2 | C17: SL-Net | D17: mIoU | E17: 87.3 | F17: =ROUND(VALUE(E17)-'7-Baseline Performance Results'!E18,4) -> 8.25
A18: SCOPUS-000475 | B18: SCOPUS-000475-6 | C18: Proposed Model | D18: mIoU | E18: 84.28 | F18: =ROUND(VALUE(E18)-'7-Baseline Performance Results'!E20,4) -> 3.08
A19: SCOPUS-000399 | B19: SCOPUS-000399-2 | C19: CA-GAN | D19: Accuracy | E19: 82.63 | F19: =ROUND(VALUE(E19)-'7-Baseline Performance Results'!E21,4) -> 9.93
A20: SCOPUS-000323 | B20: SCOPUS-000323-8 | C20: Proposed Network | D20: Accuracy | E20: 99.07 | F20: =ROUND(VALUE(E20)-'7-Baseline Performance Results'!E22,4) -> 4.48
A21: SCOPUS-000295 | B21: SCOPUS-000295-14 | C21: YOLOX-Tiny | D21: mAP@0.5 | E21: 98.2 | F21: =ROUND(VALUE(E21)-'7-Baseline Performance Results'!E23,4) -> 1.3
A22: SCOPUS-000611 | B22: SCOPUS-000611-1 | C22: Quantized Model | D22: Accuracy | E22: 87 | F22: =ROUND(VALUE(E22)-'7-Baseline Performance Results'!E24,4) -> -10
A23: SCOPUS-000738 | B23: SCOPUS-000738-2 | C23: Patch classifier, NGB (3 channels) | D23: Accuracy | E23: 86.3 | F23: =ROUND(VALUE(E23)-'7-Baseline Performance Results'!E25,4) -> 3.8
A24: SCOPUS-000114 | B24: SCOPUS-000114-4 | C24: EnviroWeedNet | D24: Accuracy | E24: 94.5 | F24: =ROUND(VALUE(E24)-'7-Baseline Performance Results'!E26,4) -> 9.4
A25: SCOPUS-000283 | B25: SCOPUS-000283-2 | C25: YOLOv11-SNEW | D25: mAP@0.5 | E25: 91.4 | F25: =ROUND(VALUE(E25)-'7-Baseline Performance Results'!E28,4) -> 5.2
A26: SCOPUS-000276 | B26: SCOPUS-000276-3 | C26: HAPN | D26: Accuracy | E26: 96.53 | F26: =ROUND(VALUE(E26)-'7-Baseline Performance Results'!E29,4) -> 34.93
A27: SCOPUS-000246 | B27: SCOPUS-000246-1 | C27: Ours | D27: mIoU | E27: 39.66 | F27: =ROUND(VALUE(E27)-'7-Baseline Performance Results'!E30,4) -> 27.79
A28: SCOPUS-000599 | B28: SCOPUS-000599-2 | C28: VGG16 BN (Adagrad) | D28: Accuracy | E28: 98 | F28: =ROUND(VALUE(E28)-'7-Baseline Performance Results'!E31,4) -> 2
A29: SCOPUS-000280 | B29: SCOPUS-000280-5 | C29: YOLOv12-BDA | D29: mAP@0.5 | E29: 91.57 | F29: =ROUND(VALUE(E29)-'7-Baseline Performance Results'!E32,4) -> 4.67
A30: SCOPUS-000063 | B30: SCOPUS-000063-7 | C30: Proposed Method | D30: mAP@0.5 | E30: 92 | F30: =ROUND(VALUE(E30)-'7-Baseline Performance Results'!E33,4) -> 11
A31: SCOPUS-000017 | B31: SCOPUS-000017-2 | C31: MESA-Net | D31: mIoU | E31: 71.35 | F31: =ROUND(VALUE(E31)-'7-Baseline Performance Results'!E34,4) -> 9.2
A32: SCOPUS-000244 | B32: SCOPUS-000244-12 | C32: WeedCLR | D32: Accuracy | E32: 91.21 | F32: =ROUND(VALUE(E32)-'7-Baseline Performance Results'!E35,4) -> 4.82
A33: SCOPUS-000320 | B33: SCOPUS-000320-2 | C33: YOLOv7 | D33: mAP@0.5 | E33: 88 | F33: =ROUND(VALUE(E33)-'7-Baseline Performance Results'!E36,4) -> 9
A34: SCOPUS-000352 | B34: SCOPUS-000352-6 | C34: convnext_unet | D34: mIoU | E34: 88.1 | F34: =ROUND(VALUE(E34)-'7-Baseline Performance Results'!E39,4) -> 3.8
A35: SCOPUS-000175 | B35: SCOPUS-000175-3 | C35: Yolov8s | D35: mAP@0.5 | E35: 76.9 | F35: =ROUND(VALUE(E35)-'7-Baseline Performance Results'!E40,4) -> 1.4
A36: SCOPUS-000574 | B36: SCOPUS-000574-2 | C36: Proposed | D36: mIoU | E36: 73.53 | F36: =ROUND(VALUE(E36)-'7-Baseline Performance Results'!E41,4) -> 7.74
A37: SCOPUS-000358 | B37: SCOPUS-000358-5 | C37: SC-Net | D37: mIoU | E37: 87.48 | F37: =ROUND(VALUE(E37)-'7-Baseline Performance Results'!E42,4) -> 10.75
A38: SCOPUS-000265 | B38: SCOPUS-000265-5 | C38: STBNA-YOLOv5 | D38: mAP@0.5 | E38: 90.8 | F38: =ROUND(VALUE(E38)-'7-Baseline Performance Results'!E43,4) -> 6.1
A39: SCOPUS-000563 | B39: SCOPUS-000563-1 | C39: YOLOv5 | D39: mAP@0.5 | E39: 88 | F39: =ROUND(VALUE(E39)-'7-Baseline Performance Results'!E44,4) -> 35
A40: SCOPUS-000333 | B40: SCOPUS-000333-3 | C40: Mixed real + synthetic Mask R-CNN | D40: mAP@0.5 | E40: 83 | F40: =ROUND(VALUE(E40)-'7-Baseline Performance Results'!E140,4) -> 2
...

Sheet 9-Quality & Risk of Bias
A1: Domain | B1: Training-Data Barriers (RQ1) | D1: Mitigation Strategy (RQ2) | F1: Performance Reporting (RQ3 & RQ4) | J1: Experimental Context (Moderators) | N1: Methodological Credibility (RQ5) | S1: Synthetic Image Methods (RQ6) | U1: Assessment Judgments
A2: Study ID | B2: Is the specific training-data barrier(s) clearly identified and described? | C2: Is the prevalence or severity of the barrier quantified or well justified? | D2: Is the mitigation strategy clearly named and described? | E2: Is the link between the barrier and the chosen strategy explicitly justified? | F2: Are absolute performance values (before and after mitigation) reported with clear metrics? | G2: Is the baseline performance (without the mitigation) clearly reported? | H2: Is the performance gain calculated and reported transparently? | I2: Are performance results supported by uncertainty/variability evidence such as repeated runs, folds, SD, CI, or multiple seeds? | J2: Is the experimental environment clearly stated (field / UAV / greenhouse / lab / controlled)? | K2: Is dataset size (number of images or instances) clearly reported? | L2: Is the computer-vision task clearly specified (Detection / Classification / Segmentation)? | M2: Is the evaluation dataset reasonably representative of the intended operating conditions? | N2: Was a proper independent test set (or external validation) used? | O2: Was data leakage prevented? | P2: Were appropriate metrics used for the task? | Q2: Are limitations of the training data and mitigation strategy discussed? | R2: Are training/validation/test samples separated sufficiently to avoid closely related images or acquisition groups appearing across splits? | S2: If synthetic images were used, is the generation method clearly described? | T2: Is a fair comparison with non-synthetic alternatives provided? | U2: Domain-level Concern | V2: Overall Risk of Bias | W2: Applicability / Generalizability Concern
A3: SCOPUS-000349 | B3: Yes | C3: Yes | D3: Yes | E3: Yes | F3: Yes | G3: Yes | H3: Yes | I3: No | J3: Yes | K3: Yes | L3: Yes | M3: Partial | N3: Yes | O3: Yes | P3: Yes | Q3: Yes | R3: Yes | S3: Yes | T3: Yes | U3: Some concerns | V3: Low | W3: Some concerns
A4: SCOPUS-000473 | B4: Yes | C4: Yes | D4: Yes | E4: Yes | F4: Yes | G4: Yes | H4: Yes | I4: Unclear | J4: Yes | K4: Yes | L4: Yes | M4: Yes | N4: Yes | O4: Partial | P4: Yes | Q4: Yes | R4: Unclear | S4: N/A | T4: N/A | U4: Some concerns | V4: Low | W4: Low
A5: SCOPUS-000722 | B5: Yes | C5: Yes | D5: Yes | E5: Yes | F5: Yes | G5: Yes | H5: Partial | I5: No | J5: Yes | K5: Yes | L5: Yes | M5: Partial | N5: Yes | O5: Unclear | P5: Yes | Q5: Yes | R5: Unclear | S5: N/A | T5: N/A | U5: Some concerns | V5: Some concerns | W5: Some concerns
A6: SCOPUS-000153 | B6: Yes | C6: Yes | D6: Yes | E6: Yes | F6: Yes | G6: Yes | H6: Yes | I6: No | J6: Yes | K6: Yes | L6: Yes | M6: Yes | N6: Yes | O6: Yes | P6: Yes | Q6: Yes | R6: Yes | S6: N/A | T6: N/A | U6: Low | V6: Low | W6: Low
A7: SCOPUS-000522 | B7: Yes | C7: Partial | D7: Yes | E7: Yes | F7: Yes | G7: Yes | H7: Partial | I7: No | J7: Yes | K7: Yes | L7: Yes | M7: Yes | N7: Yes | O7: Unclear | P7: Yes | Q7: Partial | R7: Unclear | S7: N/A | T7: N/A | U7: Some concerns | V7: Some concerns | W7: Low
A8: SCOPUS-000487 | B8: Yes | C8: Yes | D8: Yes | E8: Yes | F8: Yes | G8: Yes | H8: Yes | I8: No | J8: Yes | K8: Yes | L8: Yes | M8: Yes | N8: Yes | O8: Unclear | P8: Yes | Q8: Partial | R8: Unclear | S8: Yes | T8: Yes | U8: Some concerns | V8: Some concerns | W8: Low
A9: SCOPUS-000328 | B9: Yes | C9: Partial | D9: Yes | E9: Yes | F9: Yes | G9: Yes | H9: Partial | I9: No | J9: Yes | K9: Yes | L9: Yes | M9: Yes | N9: Yes | O9: Unclear | P9: Yes | Q9: Partial | R9: Unclear | S9: N/A | T9: N/A | U9: Some concerns | V9: Some concerns | W9: Low
A10: SCOPUS-000234 | B10: Yes | C10: Yes | D10: Yes | E10: Yes | F10: Yes | G10: Yes | H10: Yes | I10: No | J10: Yes | K10: Yes | L10: Yes | M10: Partial | N10: Yes | O10: Partial | P10: Yes | Q10: Partial | R10: Unclear | S10: N/A | T10: N/A | U10: Some concerns | V10: Some concerns | W10: Some concerns
A11: SCOPUS-000220 | B11: Yes | C11: Yes | D11: Yes | E11: Yes | F11: Yes | G11: Yes | H11: Yes | I11: No | J11: Yes | K11: Yes | L11: Yes | M11: Partial | N11: Yes | O11: Unclear | P11: Yes | Q11: Partial | R11: Unclear | S11: N/A | T11: N/A | U11: Some concerns | V11: Some concerns | W11: Some concerns
A12: SCOPUS-000195 | B12: Yes | C12: Partial | D12: Yes | E12: Yes | F12: Yes | G12: Yes | H12: Partial | I12: No | J12: Yes | K12: Yes | L12: Yes | M12: Yes | N12: Yes | O12: Partial | P12: Yes | Q12: Partial | R12: Unclear | S12: N/A | T12: N/A | U12: Some concerns | V12: Some concerns | W12: Low
A13: SCOPUS-000139 | B13: Yes | C13: Yes | D13: Yes | E13: Yes | F13: Yes | G13: Yes | H13: Yes | I13: Unclear | J13: Yes | K13: Yes | L13: Yes | M13: Partial | N13: Yes | O13: Unclear | P13: Yes | Q13: Yes | R13: Unclear | S13: Yes | T13: Yes | U13: Some concerns | V13: Some concerns | W13: Some concerns
... A24: SCOPUS-000611 | B24: Yes | C24: Yes | D24: Yes | E24: Yes | F24: Yes | G24: Yes | H24: Partial | I24: No | J24: Partial | K24: Yes | L24: Yes | M24: Partial | N24: Yes | O24: No | P24: Yes | Q24: Yes | R24: No | S24: N/A | T24: N/A | U24: High | V24: High | W24: Some concerns
A25: SCOPUS-000738 | B25: Yes | C25: Yes | D25: Yes | E25: Yes | F25: Yes | G25: Yes | H25: Partial | I25: No | J25: Yes | K25: Yes | L25: Yes | M25: Yes | N25: Yes | O25: Partial | P25: Yes | Q25: Yes | R25: Partial | U25: Some concerns | V25: Some concerns | W25: Low
A26: SCOPUS-000114 | B26: Yes | C26: Partial | D26: Yes | E26: Partial | F26: Partial | G26: Partial | H26: Partial | I26: No | J26: Partial | K26: Partial | L26: Yes | M26: Partial | N26: Unclear | O26: Unclear | P26: Yes | Q26: Partial | R26: Unclear | S26: N/A | T26: N/A | U26: Some concerns | V26: Some concerns | W26: Some concerns
A27: SCOPUS-000366 | B27: Yes | C27: Yes | D27: Yes | E27: Yes | F27: Yes | G27: Yes | H27: Partial | I27: No | J27: Yes | K27: Yes | L27: Yes | M27: Partial | N27: Yes | O27: Unclear | P27: Yes | Q27: Partial | R27: Unclear | U27: Some concerns | V27: Some concerns | W27: Some concerns
A28: SCOPUS-000283 | B28: Yes | C28: Yes | D28: Yes | E28: Yes | F28: Yes | G28: Yes | H28: Yes | I28: No | J28: Yes | K28: Yes | L28: Yes | M28: Yes | N28: Yes | O28: No | P28: Yes | Q28: Partial | R28: No | S28: N/A | T28: N/A | U28: High | V28: High | W28: Some concerns
A29: SCOPUS-000276 | B29: Yes | C29: Yes | D29: Yes | E29: Yes | F29: Yes | G29: Yes | H29: Partial | I29: No | J29: Yes | K29: Yes | L29: Yes | M29: Yes | N29: Partial | O29: Unclear | P29: Yes | Q29: Yes | R29: Unclear | S29: N/A | T29: N/A | U29: Some concerns | V29: Some concerns | W29: Some concerns
A30: SCOPUS-000246 | B30: Yes | C30: Yes | D30: Yes | E30: Yes | F30: Yes | G30: Yes | H30: Yes | I30: No | J30: Yes | K30: Yes | L30: Yes | M30: Yes | N30: Yes | O30: Yes | P30: Yes | Q30: Yes | R30: Yes | S30: N/A | T30: N/A | U30: Low | V30: Low | W30: Low
A31: SCOPUS-000599 | B31: Yes | C31: Partial | D31: Yes | E31: Yes | F31: Yes | G31: Yes | H31: Partial | I31: Partial | J31: Yes | K31: Yes | L31: Yes | M31: Yes | N31: Yes | O31: Unclear | P31: Yes | Q31: Partial | R31: Unclear | U31: Some concerns | V31: Some concerns | W31: Some concerns
A32: SCOPUS-000280 | B32: Yes | C32: Yes | D32: Yes | E32: Yes | F32: Yes | G32: Yes | H32: Partial | I32: No | J32: Yes | K32: Yes | L32: Yes | M32: Yes | N32: Yes | O32: Unclear | P32: Yes | Q32: Yes | R32: Unclear | S32: N/A | T32: N/A | U32: Some concerns | V32: Some concerns | W32: Low
A33: SCOPUS-000063 | B33: Yes | C33: Yes | D33: Yes | E33: Yes | F33: Yes | G33: Yes | H33: Partial | I33: Yes | J33: Yes | K33: Yes | L33: Yes | M33: Partial | N33: Yes | O33: Unclear | P33: Yes | Q33: Partial | R33: Unclear | S33: Yes | T33: Yes | U33: Some concerns | V33: Some concerns | W33: Some concerns
A34: SCOPUS-000017 | B34: Yes | C34: Yes | D34: Yes | E34: Yes | F34: Yes | G34: Yes | H34: Partial | I34: No | J34: Yes | K34: Yes | L34: Yes | M34: Yes | N34: Yes | O34: Unclear | P34: Yes | Q34: Partial | R34: Unclear | S34: N/A | T34: N/A | U34: Some concerns | V34: Some concerns | W34: Low
A35: SCOPUS-000244 | B35: Yes | C35: Yes | D35: Yes | E35: Yes | F35: Yes | G35: Yes | H35: Partial | I35: No | J35: Yes | K35: Yes | L35: Yes | M35: Yes | N35: Yes | O35: Unclear | P35: Yes | Q35: Yes | R35: Unclear | S35: N/A | T35: N/A | U35: Some concerns | V35: Some concerns | W35: Low
A36: SCOPUS-000320 | B36: Yes | C36: Yes | D36: Yes | E36: Yes | F36: Yes | G36: Yes | H36: Partial | I36: No | J36: Yes | K36: Yes | L36: Yes | M36: Yes | N36: Yes | O36: No | P36: Yes | Q36: Partial | R36: No | S36: N/A | T36: N/A | U36: High | V36: High | W36: Some concerns
A37: SCOPUS-000086 | B37: Yes | C37: Yes | D37: Yes | E37: Yes | F37: Yes | G37: Yes | H37: Partial | I37: Partial | J37: Yes | K37: Yes | L37: Yes | M37: Yes | N37: Yes | O37: Yes | P37: Yes | Q37: Yes | R37: Yes | S37: N/A | T37: N/A | U37: Low | V37: Low | W37: Low
A38: SCOPUS-000652 | B38: Yes | C38: Partial | D38: Yes | E38: Yes | F38: Yes | G38: Yes | H38: Partial | I38: No | J38: Yes | K38: Yes | L38: Yes | M38: Partial | N38: Yes | O38: Unclear | P38: Yes | Q38: Partial | R38: Unclear | S38: N/A | T38: N/A | U38: Some concerns | V38: Some concerns | W38: Some concerns
A39: SCOPUS-000146 | B39: Yes | C39: Yes | D39: Yes | E39: Yes | F39: Yes | G39: Yes | H39: Partial | I39: No | J39: Yes | K39: Yes | L39: Yes | M39: Partial | N39: Yes | O39: Unclear | P39: Yes | Q39: Partial | R39: Unclear | S39: N/A | T39: N/A | U39: Some concerns | V39: Some concerns | W39: Some concerns
A40: SCOPUS-000352 | B40: Yes | C40: Yes | D40: Yes | E40: Yes | F40: Yes | G40: Yes | H40: Partial | I40: No | J40: Yes | K40: Yes | L40: Yes | M40: Yes | N40: Yes | O40: Unclear | P40: Yes | Q40: Partial | R40: Unclear | S40: N/A | T40: N/A | U40: Some concerns | V40: Some concerns | W40: Low
A41: SCOPUS-000175 | B41: Yes | C41: Yes | D41: Yes | E41: Yes | F41: Yes | G41: Yes | H41: Partial | I41: No | J41: Yes | K41: Yes | L41: Yes | M41: Yes | N41: Yes | O41: Unclear | P41: Yes | Q41: Partial | R41: Unclear | S41: N/A | T41: N/A | U41: Some concerns | V41: Some concerns | W41: Low
A42: SCOPUS-000574 | B42: Yes | C42: Yes | D42: Yes | E42: Yes | F42: Yes | G42: Yes | H42: Partial | I42: No | J42: Yes | K42: Yes | L42: Yes | M42: Yes | N42: Yes | O42: Yes | P42: Yes | Q42: Yes | R42: Yes | S42: N/A | T42: N/A | U42: Low | V42: Low | W42: Low
A43: SCOPUS-000358 | B43: Yes | C43: Partial | D43: Yes | E43: Yes | F43: Yes | G43: Yes | H43: Partial | I43: No | J43: Yes | K43: Yes | L43: Yes | M43: Partial | N43: Unclear | O43: Unclear | P43: Yes | Q43: Partial | R43: Unclear | S43: N/A | T43: N/A | U43: Some concerns | V43: Some concerns | W43: Some concerns
... A74: SCOPUS-000065 | B74: Yes | C74: Yes | D74: Yes | E74: Yes | F74: Yes | G74: Yes | H74: Yes | I74: No | J74: Yes | K74: Yes | L74: Yes | M74: Partial | N74: Yes | O74: Unclear | P74: Yes | Q74: Yes | R74: Unclear | S74: N/A | T74: N/A | U74: Some concerns | V74: Some concerns | W74: High
A75: SCOPUS-000030 | B75: Yes | C75: Yes | D75: Yes | E75: Yes | F75: Yes | G75: Yes | H75: Partial | I75: No | J75: Yes | K75: Yes | L75: Yes | M75: Partial | N75: Yes | O75: Unclear | P75: Yes | Q75: Partial | R75: Unclear | U75: Some concerns | V75: Some concerns | W75: Some concerns
A76: WEBSCI-000402 | B76: Yes | C76: Partial | D76: Yes | E76: Yes | F76: Yes | G76: Yes | H76: Yes | I76: No | J76: Yes | K76: Yes | L76: Yes | M76: Partial | N76: Partial | O76: No | P76: Yes | Q76: Partial | R76: Yes | U76: Low | V76: Low | W76: Low
A77: SCOPUS-000300 | B77: Yes | C77: Yes | D77: Yes | E77: Yes | F77: Yes | G77: Yes | H77: Partial | I77: No | J77: Yes | K77: Yes | L77: Yes | M77: Yes | N77: Yes | O77: Unclear | P77: Yes | Q77: Yes | R77: Unclear | S77: N/A | T77: N/A | U77: Some concerns | V77: Some concerns | W77: Some concerns
A78: SCOPUS-000099 | B78: Yes | C78: Yes | D78: Yes | E78: Yes | F78: Yes | G78: Yes | H78: Yes | I78: No | J78: Yes | K78: Yes | L78: Yes | M78: Yes | N78: Yes | O78: Unclear | P78: Yes | Q78: Yes | R78: Unclear | S78: N/A | T78: N/A | U78: Some concerns | V78: Some concerns | W78: Some concerns
A79: SCOPUS-000287 | B79: Yes | C79: Partial | D79: Yes | E79: Yes | F79: Yes | G79: Yes | H79: Partial | I79: No | J79: Yes | K79: Yes | L79: Yes | M79: Yes | N79: Yes | O79: Unclear | P79: Yes | Q79: Yes | R79: Unclear | S79: N/A | T79: N/A | U79: Some concerns | V79: Some concerns | W79: Some concerns
A80: SCOPUS-000290 | B80: Yes | C80: Partial | D80: Yes | E80: Yes | F80: Yes | G80: Yes | H80: Yes | I80: No | J80: Yes | K80: Yes | L80: Yes | M80: Yes | N80: Yes | O80: Unclear | P80: Yes | Q80: Yes | R80: Unclear | S80: N/A | T80: N/A | U80: Some concerns | V80: Some concerns | W80: Some concerns
...
